<?xml version="1.0"?>
<robot name="visual">
<!-- E. Culurciello, March 2021 -->
<!-- basic 2-fingers gripper -->
  <link name="base">
  <inertial>
    <mass value="0.1"/>
    <inertia ixx="1" ixy="0" ixz="0" iyy="1" iyz="0" izz="1" />
    <origin/>
  </inertial>
    <visual>
      <geometry>
        <box size="0.08 0.01 0.05"/>
      </geometry>
      <origin rpy="0 0 0" xyz="0 0 0"/>
      <material name="B">
        <color rgba="1 1 1 1"/>
      </material>
    </visual>
  <collision>
      <origin rpy="0 0 0" xyz="0 -0.1 0"/>
    <geometry>
        <box size="0.08 .02 .03"/>
    </geometry>
    <contact_coefficients mu="0" kp="1000.0" kd="1.0"/>
  </collision>
  </link>

  <link name="left_fingertip">
  <inertial>
    <mass value="0.1"/>
    <inertia ixx="1" ixy="0" ixz="0" iyy="1" iyz="0" izz="1" />
    <origin/>
  </inertial>
    <visual>
      <geometry>
        <box size="0.01 .04 .01"/>
      </geometry>
      <origin rpy="0 0 0" xyz="0 0 0"/>
      <material name="white">
        <color rgba="1 1 1 1"/>
      </material>
    </visual>
  <collision>
      <origin rpy="0 0 0" xyz="0 0 0"/>
    <geometry>
        <box size="0.01 .04 .01"/>
    </geometry>
    <contact_coefficients mu="0" kp="1000.0" kd="1.0"/>
  </collision>
  </link>

  <joint name="base_to_left_fingertip" type="prismatic">
    <axis xyz="1 0 0"/>
    <limit effort="1.0" lower="0" upper="1" velocity="0.1"/>
    <parent link="base"/>
    <child link="left_fingertip"/>
    <origin xyz="-0.035 -0.04 0.0"/>
  </joint>

  <link name="right_fingertip">
  <inertial>
    <mass value="0.1"/>
    <inertia ixx="1" ixy="0" ixz="0" iyy="1" iyz="0" izz="1" />
    <origin/>
  </inertial>
    <visual>
      <geometry>
        <box size="0.01 .04 .01"/>
      </geometry>
      <origin rpy="0 0 0" xyz="0 0 0"/>
      <material name="white">
        <color rgba="1 1 1 1"/>
      </material>
    </visual>
  <collision>
     <origin rpy="0 0 0" xyz="0 0 0"/>
    <geometry>
        <box size="0.01 .04 .01"/>
    </geometry>
    <contact_coefficients mu="0" kp="1000.0" kd="1.0"/>
  </collision>
  </link>

  <joint name="base_to_right_fingertip" type="prismatic">
    <axis xyz="1 0 0"/>
    <limit effort="1.0" lower="-1" upper="0.0" velocity="0.1"/>
    <parent link="base"/>
    <child link="right_fingertip"/>
    <origin xyz="0.035 -0.04 -0.00"/>
  </joint>

</robot>