<?xml version="1.0" encoding="utf-8" ?>
<!-- This URDF was crafted by the one and only Feliping. RFIDudes 2 the future -->

<robot name="skaren">
    <link name="base_link">
        <inertial>
            <origin xyz="0 0 0" rpy="0 0 0" />
            <mass value="15.652" />
            <inertia ixx="0.077426" ixy="1.6502E-15" ixz="-3.9864E-16" iyy="0.08833" iyz="9.4391E-06" izz="0.07706" />
        </inertial>
        <visual>
            <geometry>
                <mesh filename="package://skaren/meshes/visual/base.stl" />
            </geometry>
            <material name="">
                <color rgba="0.75294 0.75294 0.75294 1" />
            </material>
        </visual>
        <collision>
            <origin xyz="0 0 0" rpy="0 0 0" />
            <geometry>
                <mesh filename="package://skaren/meshes/collision/base.stl" />
            </geometry>
        </collision>
    </link>
    
    <link name="humero">
        <inertial>
            <origin xyz="0 0 0" rpy="0 0 0" />
            <mass value="5" />
            <inertia ixx="0.019084" ixy="-1.4804E-10" ixz="-2.2963E-09" iyy="0.020036" iyz="-0.00043182" izz="0.0013447" />
        </inertial>

        <visual>
            <origin xyz="0 0 0" rpy="0 0 0" />
            <geometry>
                <mesh filename="package://skaren/meshes/visual/link_1.stl" />
            </geometry>
            <material name="">
                <color rgba="0.75294 0.75294 0.75294 1" />
            </material>
        </visual>
        <collision>
            <origin xyz="0 0 0" rpy="0 0 0" />
            <geometry>
                <mesh filename="package://skaren/meshes/visual/link_1.stl" />
            </geometry>
        </collision>
    </link>
    <link name="antebrazo">
        <inertial>
            <origin xyz="0 0 0" rpy="0 0 0" />
            <mass value="5" />
            <inertia ixx="0.019084" ixy="-1.4804E-10" ixz="-2.2963E-09" iyy="0.020036" iyz="-0.00043182" izz="0.0013447" />
        </inertial>

        <visual>
            <origin xyz="0 0 0.15" rpy="0 0 0" />
            <geometry>
                <mesh filename="package://skaren/meshes/visual/link_2.stl" />
            </geometry>
            <material name="">
                <color rgba="0.75294 0.75294 0.75294 1" />
            </material>
        </visual>
        <collision>
            <origin xyz="0 0 0.15" rpy="0 0 0" />
            <geometry>
                <mesh filename="package://skaren/meshes/visual/link_2.stl" />
            </geometry>
        </collision>
    </link>

    <joint name="hombro" type="revolute">
        <origin xyz="0 0 0" rpy="0 0 0" />
        <parent link="base_link" />
        <child link="antebrazo" />
        <axis xyz="0 0 1" />
        <limit lower="-1.57" upper="1.57" effort="45" velocity="8" />
    </joint>

    <joint name="codo" type="revolute">
        <origin xyz="0 0 0" rpy="0 0 0" />
        <parent link="humero" />
        <child link="humero" />
        <axis xyz="0 0 1" />
        <limit lower="-1.57" upper="1.57" effort="45" velocity="8" />
    </joint>
</robot>

