<?xml version="1.0" encoding="utf-8" ?>
<robot name="scarapris">

    <material name="blue">
        <color rgba="0 0 0.8 1"/>
    </material>
    <material name="black">
        <color rgba="0 0 0 1"/>
    </material>
    <material name="white">
        <color rgba="1 1 1 1"/>
    </material>
    <material name="applegreen" >
        <color rgba="0.4627450980392157 0.803921568627451 0.14901960784313725 1.0" />
    </material>
    <material name="babypink" >
        <color rgba="1.0 0.7176470588235294 0.807843137254902 1.0" />
    </material>

    <link name="base_link">
        <inertial>
            <origin xyz="0 0 0" rpy="0 0 0" />
            <mass value="15.652" />
            <inertia ixx="0.077426" ixy="1.6502E-15" ixz="-3.9864E-16" iyy="0.08833" iyz="9.4391E-06" izz="0.07706" />
        </inertial>
        <visual>
            <geometry>
                <mesh filename="package://scarapris/meshes/visual/base.stl" />
            </geometry>
            <material name="black"/>
        </visual>
        <collision>
            <origin xyz="0 0 0" rpy="0 0 0" />
            <geometry>
                <mesh filename="package://scarapris/meshes/collision/base.stl" />
            </geometry>
        </collision>
    </link>
    
    <link name="humero">
        <inertial>
            <origin xyz="0 0 0" rpy="0 0 0" />
            <mass value="5" />
            <inertia ixx="0.019084" ixy="-1.4804E-10" ixz="-2.2963E-09" iyy="0.020036" iyz="-0.00043182" izz="0.0013447" />
        </inertial>

        <visual>
            <origin xyz="0 0 0" rpy="0 0 0" />
            <geometry>
                <mesh filename="package://scarapris/meshes/visual/link_1.stl" />
            </geometry>
            <material name="applegreen"/>
        </visual>
        <collision>
            <origin xyz="0 0 0" rpy="0 0 0" />
            <geometry>
                <mesh filename="package://scarapris/meshes/visual/link_1.stl" />
            </geometry>
        </collision>
    </link>
    <!-- <link name="rod">
        <inertial>
            <origin xyz="0 0 0" rpy="0 0 0" />
            <mass value="5" />
            <inertia ixx="0.019084" ixy="-1.4804E-10" ixz="-2.2963E-09" iyy="0.020036" iyz="-0.00043182" izz="0.0013447" />
        </inertial>

        <visual>
            <origin xyz="0 0 0.756" rpy="0 0 0" />
            <geometry>
                <mesh filename="package://scarapris/meshes/visual/link_1_rod.stl" />
            </geometry>
            <material name="blue"/>
        </visual>
        <collision>
            <origin xyz="0 0 0.756" rpy="0 0 0" />
            <geometry>
                <mesh filename="package://scarapris/meshes/visual/link_1_rod.stl" />
            </geometry>
        </collision>
    </link> -->

    <link name="antebrazo">
        <inertial>
            <origin xyz="0 0 0" rpy="0 0 0" />
            <mass value="5" />
            <inertia ixx="0.019084" ixy="-1.4804E-10" ixz="-2.2963E-09" iyy="0.020036" iyz="-0.00043182" izz="0.0013447" />
        </inertial>

        <visual>
            <origin xyz="0 0 0" rpy="0 0 0" />
            <geometry>
                <mesh filename="package://scarapris/meshes/visual/link_2.stl" />
            </geometry>
            <material name="babypink"/>
        </visual>
        <collision>
            <origin xyz="0 0 0" rpy="0 0 0" />
            <geometry>
                <mesh filename="package://scarapris/meshes/visual/link_2.stl" />
            </geometry>
        </collision>
    </link>
    <link name="off_x">
        <inertial>
            <origin xyz="0 0 0" rpy="0 0 0" />
            <mass value="5" />
            <inertia ixx="0.019084" ixy="-1.4804E-10" ixz="-2.2963E-09" iyy="0.020036" iyz="-0.00043182" izz="0.0013447" />
        </inertial>

        <visual>
            <origin xyz="0 0 0" rpy="0 0 0" />
            <geometry>
                <mesh filename="package://scarapris/meshes/visual/link_3.stl" />
            </geometry>
            <material name="applegreen"/>
        </visual>
        <collision>
            <origin xyz="0 0 0" rpy="0 0 0" />
            <geometry>
                <mesh filename="package://scarapris/meshes/visual/link_3.stl" />
            </geometry>
        </collision>
    </link>
    <link name="pris_z">
        <inertial>
            <origin xyz="0 0 0" rpy="0 0 0" />
            <mass value="5" />
            <inertia ixx="0.019084" ixy="-1.4804E-10" ixz="-2.2963E-09" iyy="0.020036" iyz="-0.00043182" izz="0.0013447" />
        </inertial>

        <visual>
            <origin xyz="0 0 0" rpy="0 0 0" />
            <geometry>
                <mesh filename="package://scarapris/meshes/visual/pris_z.stl" />
            </geometry>
            <material name="white"/>
        </visual>
        <collision>
            <origin xyz="0 0 0" rpy="0 0 0" />
            <geometry>
                <mesh filename="package://scarapris/meshes/visual/pris_z.stl" />
            </geometry>
        </collision>
    </link>
    <link name="brush">
        <inertial>
            <origin xyz="0 0 0" rpy="0 0 0" />
            <mass value="5" />
            <inertia ixx="0.019084" ixy="-1.4804E-10" ixz="-2.2963E-09" iyy="0.020036" iyz="-0.00043182" izz="0.0013447" />
        </inertial>

        <visual>
            <origin xyz="0 0 0" rpy="0 0 0" />
            <geometry>
                <mesh filename="package://scarapris/meshes/visual/brush.stl" />
            </geometry>
            <material name="babypink"/>
        </visual>
        <collision>
            <origin xyz="0 0 0" rpy="0 0 0" />
            <geometry>
                <mesh filename="package://scarapris/meshes/visual/brush.stl" />
            </geometry>
        </collision>
    </link>

    <joint name="hombro" type="revolute">
        <origin xyz="0 0 0" rpy="0 0 0" />
        <parent link="base_link" />
        <child link="humero" />
        <axis xyz="0 0 1" />
        <limit lower="-1.57" upper="1.57" effort="45" velocity="8" />
    </joint>

    <joint name="codo" type="revolute">
        <origin xyz="0.15 0 0.25" rpy="0 0 0" />
        <parent link="humero" />
        <child link="antebrazo" />
        <axis xyz="0 0 1" />
        <limit lower="-3.14" upper="3.14" effort="45" velocity="8" />
    </joint>

    <joint name="pris_x" type="prismatic">
        <origin xyz="0 0 -0.07" rpy="0 0 0" />
        <parent link="antebrazo" />
        <child link="off_x" />
        <axis xyz="1 0 0" />
        <limit lower="0" upper="0.1" />
    </joint>

    <joint name="pris_z" type="prismatic">
        <origin xyz="0 0.039 -0.05" rpy="0 0 0" />
        <parent link="off_x" />
        <child link="pris_z" />
        <axis xyz="0 0 1" />
        <limit lower="-0.06" upper="0" />
    </joint>

    <joint name="brush" type="fixed">
        <origin xyz="0 0 -0.07" rpy="0 0 0" />
        <parent link="pris_z" />
        <child link="brush" />
    </joint>
    <!-- <joint name="rodamiento" type="fixed">
        <origin xyz="0 0 0" rpy="0 0 0" />
        <parent link="humero" />
        <child link="rod" />
    </joint> -->

</robot>

