<?xml version="1.0"?>
<robot name="base_link_only">
    <material name="silver">
        <color rgba="0.75 0.75 0.75 1.0"/> <!-- Plateado -->
    </material>
    <material name="black">
		<color rgba="0.1 0.1 0.1 1.0"/> <!-- Plomo oscuro metálico -->
	</material>
	<material name="yellow">
        <color rgba="1.0 1.0 0.0 1.0"/> <!-- Amarillo -->
	</material>


    <link name="base_link">
        <visual>
            <geometry>
                <mesh filename="ME5150_tutorials\modelos\base_movil\meshes\base_scaled_v1.stl"/>
            </geometry>
            <material name="silver"/>
        </visual>
        <inertial>
            <mass value="0.4599"/>
            <origin xyz="0.0 0.0 -0.076005"/>
            <inertia ixx="625100000" ixy="-0.00000302" ixz="-6586" iyy="2636000000" iyz="-0.000002321" izz="2036000000"/>
        </inertial>
    </link>

    <!-- Agregar objeto adicional al enlace base_link -->
    <link name="motor_dc_1">
        <visual>
            <geometry>
				<mesh filename= "ME5150_tutorials\modelos\base_movil\meshes\motor_scaled_v1.stl"/>
			</geometry>
            <material name= "yellow"/>
			<origin xyz="0.0 0.0 0.0" rpy="0.0 0.0 0.0"/> <!-- Posición relativa al enlace base_link -->
        </visual>
        <inertial>
            <mass value= "0.182431"/>
            <origin xyz= "0.017103 0.0 -0.064"/>
            <inertia ixx= "11974059" ixy="6925" ixz="44273" iyy="60417029" iyz="118" izz="61898680"/>
        </inertial>
    </link>
	<link name="motor_dc_2">
        <visual>
            <geometry>
				<mesh filename= "ME5150_tutorials\modelos\base_movil\meshes\motor_scaled_v1.stl"/>
			</geometry>
            <material name= "yellow"/>
			<origin xyz="0.0 0.0 0.0" rpy="0.0 0.0 0.0"/> <!-- Posición relativa al enlace base_link -->
        </visual>
        <inertial>
            <mass value= "0.182431"/>
            <origin xyz= "0.017103 0.0 -0.064"/>
            <inertia ixx= "11974059" ixy="6925" ixz="44273" iyy="60417029" iyz="118" izz="61898680"/>
        </inertial>
    </link>
	<link name="motor_dc_3">
        <visual>
            <geometry>
				<mesh filename= "ME5150_tutorials\modelos\base_movil\meshes\motor_scaled_v1.stl"/>
			</geometry>
            <material name= "yellow"/>
			<origin xyz="0.0 0.0 0.0" rpy="0.0 0.0 0.0"/> <!-- Posición relativa al enlace base_link -->
        </visual>
        <inertial>
            <mass value= "0.182431"/>
            <origin xyz= "0.017103 0.0 -0.064"/>
            <inertia ixx= "11974059" ixy="6925" ixz="44273" iyy="60417029" iyz="118" izz="61898680"/>
        </inertial>
    </link>
	<link name="motor_dc_4">
        <visual>
            <geometry>
				<mesh filename= "ME5150_tutorials\modelos\base_movil\meshes\motor_scaled_v1.stl"/>
			</geometry>
            <material name= "yellow"/>
			<origin xyz="0.0 0.0 0.0" rpy="0.0 0.0 0.0"/> <!-- Posición relativa al enlace base_link -->
        </visual>
        <inertial>
            <mass value= "0.182431"/>
            <origin xyz= "0.017103 0.0 -0.064"/>
            <inertia ixx= "11974059" ixy="6925" ixz="44273" iyy="60417029" iyz="118" izz="61898680"/>
        </inertial>
    </link>
    
    <joint name="motor_dc_1_joint" type="fixed">
        <parent link="base_link"/>
        <child link="motor_dc_1"/>
        <origin xyz="0.06425 0.043487 -0.01287" rpy="-1.5708 0.0 3.14"/>
    </joint>
	<joint name="motor_dc_2_joint" type="fixed">
        <parent link="base_link"/>
        <child link="motor_dc_2"/>
        <origin xyz="0.06425 -0.043487 -0.01287" rpy="1.5708 0.0 3.14"/>
    </joint>
	<joint name="motor_dc_3_joint" type="fixed">
        <parent link="base_link"/>
        <child link="motor_dc_3"/>
        <origin xyz="-0.06425 0.043487 -0.01287" rpy="1.5708 0.0 0.0"/>
    </joint>
	<joint name="motor_dc_4_joint" type="fixed">
        <parent link="base_link"/>
        <child link="motor_dc_4"/>
        <origin xyz="-0.06425 -0.043487 -0.01287" rpy="-1.5708 0.0 0.0"/>
    </joint>
    
	<link name="wheel_1">
        <visual>
            <geometry>
                <mesh filename="ME5150_tutorials\modelos\base_movil\meshes\ruedader.stl"/>
            </geometry>
            <material name="black"/>
			<origin xyz="0.0 0.0 0.0" rpy="0.0 0.0 0.0"/>
        </visual>
        <collision>
            <origin xyz="0.0 0.0 0.0" rpy="0.0 0.0 0.0"/>
            <geometry>
                <mesh filename="ME5150_tutorials\modelos\base_movil\meshes\cilindro_ruedas_mesh.stl"/>
            </geometry>
        </collision>
        <inertial>
            <mass value="0.27282"/>
            <origin xyz="0.0 0.0 0.0"/>
            <inertia ixx="60736443" ixy="-0.0003584" ixz="-0.00000956" iyy="60741948" iyz="-0.0001412" izz="71971219"/>
        </inertial>
    </link>
	<link name="wheel_2">
        <visual>
            <geometry>
                <mesh filename="ME5150_tutorials\modelos\base_movil\meshes\ruedaizq.stl"/>
            </geometry>
            <material name="black"/>
			<origin xyz="0.0 0.0 0.0" rpy="0.0 0.0 0.0"/> 
        </visual>
        <collision>
            <origin xyz="0.0 0.0 0.0" rpy="0.0 0.0 0.0"/>
            <geometry>
                <mesh filename="ME5150_tutorials\modelos\base_movil\meshes\cilindro_ruedas_mesh.stl"/>
            </geometry>
        </collision>
        <inertial>
            <mass value="0.27282"/>
            <origin xyz="0.0 0.0 0.0"/>
            <inertia ixx="60736443" ixy="-0.0003584" ixz="-0.00000956" iyy="60741948" iyz="-0.0001412" izz="71971219"/>
        </inertial>
    </link>
	<link name="wheel_3">
        <visual>
            <geometry>
                <mesh filename="ME5150_tutorials\modelos\base_movil\meshes\ruedaizq.stl"/>
            </geometry>
            <material name="black"/>
			<origin xyz="0.0 0.0 0.0" rpy="0.0 0.0 0.0"/>
        </visual>
        <collision>
            <origin xyz="0.0 0.0 0.0" rpy="0.0 0.0 0.0"/>
            <geometry>
                <mesh filename="ME5150_tutorials\modelos\base_movil\meshes\cilindro_ruedas_mesh.stl"/>
            </geometry>
        </collision>
        <inertial>
            <mass value="0.27282"/>
            <origin xyz="0.0 0.0 0.0"/>
            <inertia ixx="60736443" ixy="-0.0003584" ixz="-0.00000956" iyy="60741948" iyz="-0.0001412" izz="71971219"/>
        </inertial>
    </link>
	<link name="wheel_4">
        <visual>
            <geometry>
                <mesh filename="ME5150_tutorials\modelos\base_movil\meshes\ruedader.stl"/>
            </geometry>
            <material name="black"/>
			<origin xyz="0.0 0.0 0.0" rpy="0.0 0.0 0.0"/>
        </visual>
        <collision>
            <origin xyz="0.0 0.0 0.0" rpy="0.0 0.0 0.0"/>
            <geometry>
                <mesh filename="ME5150_tutorials\modelos\base_movil\meshes\cilindro_ruedas_mesh.stl"/>
            </geometry>
        </collision>
        <inertial>
            <mass value="0.27282"/>
            <origin xyz="0.0 0.0 0.0"/>
            <inertia ixx="60736443" ixy="-0.0003584" ixz="-0.00000956" iyy="60741948" iyz="-0.0001412" izz="71971219"/>
        </inertial>
    </link>
  
    <joint name="rueda1" type="continuous">
        <axis xyz="0 0 1"/>
        <parent link="motor_dc_1"/>
        <child link="wheel_1"/>
        <origin xyz="0.0 0.0 -0.027043" rpy="0 3.14 0"/> <!--1.570796-->
    </joint>
	<joint name="rueda2" type="continuous">
        <axis xyz="0 0 1"/>
        <parent link="motor_dc_2"/>
        <child link="wheel_2"/>
        <origin xyz="0.0 0.0 -0.027043" rpy="0 -3.14 0"/>
    </joint>
	<joint name="rueda3" type="continuous">
        <axis xyz="0 0 1"/>
        <parent link="motor_dc_3"/>
        <child link="wheel_3"/>
        <origin xyz="0.0 0.0 -0.027043" rpy="-3.14 0 0"/>
    </joint>
	<joint name="rueda4" type="continuous">
        <axis xyz="0 0 1"/>
        <parent link="motor_dc_4"/>
        <child link="wheel_4"/>
        <origin xyz="0.0 0.0 -0.027043" rpy="3.14 0 0"/>
    </joint> 
    
</robot>
